Workbook

Sheet Dashboard
B1: STRIDEWEAR FOOTWEAR | H1: Select Customer Segment | J1: All | K1: =IF(J1="All",SUM('Recovery Analysis'!B19:B24),SUMIF('Recovery Analysis'!A19:A24,J1,'Recovery Analysis'!B19:B24)) -> 93
B2: CUSTOMER RETENTION & SALES RECOVERY ANALYSIS
B4: Total Customer Accounts | E4: Q1 Total Orders | H4: Q3 Total Orders
B5: ='Recovery Analysis'!G14 -> 93 | E5: ='Recovery Analysis'!G15 -> 524 | H5: ='Recovery Analysis'!G16 -> 568
B7: Order Growth Volume | E7: No of At-Risk Accounts | H7: At-Risk Order Decline
B8: ='Recovery Analysis'!G17 -> 0.084 | E8: ='Recovery Analysis'!G18 -> 31 | H8: ='Recovery Analysis'!G21 -> 0.675

Sheet Chart Data
A3: Customer Segment | B3: Number of Accounts | E3: Quarter | F3: Total Orders
A4: Still Churned | B4: ='Recovery Analysis'!B6 -> 23 | E4: Q1 | F4: 524
A5: Stable / Active | E5: Q2 | F5: 339
A6: Recovered in Q3 | B6: 13 | E6: Q3 | F6: 568
A7: New Trial Accounts | B7: 8
A8: Inactive / Other | B8: 6
A9: Critical Decline | B9: 6 | E9: At-Risk Category | F9: Accounts
E10: Still Churned | F10: 23
E11: Critical Decline | F11: 8

Sheet Recovery Analysis
A1: STRIDEWEAR FOOTWEAR
A3: CHURNED SUMMARY | F3: Critical decline accounts SUMMARY | I3: At-risk account summary
A4: Metric | B4: Result | F4: Metric | G4: Result | I4: Metric | J4: Result
A5: Total accounts analysed | B5: 93 | F5: Total Q1 orders | G5: 115 | I5: At-risk accounts | J5: 31
A6: Churned accounts | B6: 23 | F6: Total Q3 orders | G6: 52 | I6: Total Q1 orders | J6: 160
A7: Q1 orders from churned accounts | B7: 45 | F7: Critical decline accounts | G7: 8 | I7: Total Q3 orders | J7: 52
A8: Churned accounts as % of total accounts | B8: 0.2473 | F8: % of total Q1 order volume | G8: 0.22 | I8: Share of total Q1 order volume | J8: 0.3053
A9: Churned Volume Share (%) | B9: 0.0859 | F9: Q1–Q3 order decline | G9: 0.5478 | I9: Q1–Q3 order decline | J9: 0.675
A11: New Trial accounts summary
A12: Metric | B12: Result | F12: total summary
A13: New trial accounts | B13: 13 | F13: Metric | G13: Result
A14: Total Q3 orders | B14: 16 | F14: Total accounts analysed | G14: 93
A15: Average Q3 orders per account | B15: 1.23 | F15: Total Q1 orders | G15: 524
F16: Total Q3 orders | G16: 568
F17: Overall Q1–Q3 order growth | G17: 0.084
A18: Customer Segment | B18: Number of Accounts | F18: At-risk accounts | G18: 31
A19: Stable / Active | B19: 37 | F19: Q1 orders from at-risk accounts | G19: 160
A20: Still Churned | B20: 23 | F20: Q3 orders from at-risk accounts | G20: 52
A21: New Trial Accounts | B21: 13 | F21: Decline in at-risk account orders | G21: 0.675
A22: Critical Decline | B22: 8 | F22: Total Q2 orders | G22: ='Validation Tracker'!J9 -> 0
A23: Recovered in Q3 | B23: 6
A24: Inactive / Other | B24: 6
A27: Customer Segment | B27: Number of Accounts
A28: =IF(Dashboard!$J$1="All",A19,IF(ROWS($A$28:A28)=1,Dashboard!$J$1,"")) -> Stable / Active | B28: =IF(A28="","",SUMIF($A$19:$A$24,A28,$B$19:$B$24)) -> 37
A29: =IF(Dashboard!$J$1="All",A20,IF(ROWS($A$28:A29)=1,Dashboard!$J$1,"")) -> Still Churned | B29: =IF(A29="","",SUMIF($A$19:$A$24,A29,$B$19:$B$24)) -> 23
A30: =IF(Dashboard!$J$1="All",A21,IF(ROWS($A$28:A30)=1,Dashboard!$J$1,"")) -> New Trial Accounts | B30: =IF(A30="","",SUMIF($A$19:$A$24,A30,$B$19:$B$24)) -> 13
A31: =IF(Dashboard!$J$1="All",A22,IF(ROWS($A$28:A31)=1,Dashboard!$J$1,"")) -> Critical Decline | B31: =IF(A31="","",SUMIF($A$19:$A$24,A31,$B$19:$B$24)) -> 8
A32: =IF(Dashboard!$J$1="All",A23,IF(ROWS($A$28:A32)=1,Dashboard!$J$1,"")) -> Recovered in Q3 | B32: =IF(A32="","",SUMIF($A$19:$A$24,A32,$B$19:$B$24)) -> 6
A33: =IF(Dashboard!$J$1="All",A24,IF(ROWS($A$28:A33)=1,Dashboard!$J$1,"")) -> Inactive / Other | B33: =IF(A33="","",SUMIF($A$19:$A$24,A33,$B$19:$B$24)) -> 6

Sheet Validation pivot
A3: Count of Order Pay | B3: Column Labels
A4: Row Labels | B4: Q1 | C4: Q2 | D4: Q3 | E4: Grand Total
A5: Account 001 | B5: 8 | C5: 17 | D5: 14 | E5: 39
A6: Account 002 | B6: 2 | E6: 2
A7: Account 003 | B7: 2 | C7: 2 | D7: 4 | E7: 8
A8: Account 004 | B8: 4 | E8: 4
A9: Account 005 | B9: 54 | C9: 49 | D9: 71 | E9: 174
A10: Account 006 | B10: 25 | C10: 17 | D10: 14 | E10: 56
A11: Account 007 | B11: 45 | C11: 27 | D11: 69 | E11: 141
A12: Account 008 | B12: 14 | C12: 3 | D12: 4 | E12: 21
A13: Account 009 | B13: 37 | C13: 42 | D13: 71 | E13: 150
A14: Account 010 | B14: 68 | C14: 12 | D14: 58 | E14: 138
A15: Account 011 | B15: 1 | C15: 6 | D15: 13 | E15: 20
A16: Account 012 | B16: 15 | C16: 12 | D16: 4 | E16: 31
A17: Account 013 | B17: 4 | C17: 1 | D17: 2 | E17: 7
A18: Account 014 | B18: 7 | C18: 8 | D18: 6 | E18: 21
A19: Account 015 | B19: 12 | C19: 2 | D19: 3 | E19: 17
A20: Account 016 | B20: 1 | E20: 1
A21: Account 017 | B21: 27 | C21: 11 | D21: 16 | E21: 54
A22: Account 018 | B22: 17 | C22: 12 | D22: 20 | E22: 49
A23: Account 019 | B23: 1 | C23: 1 | E23: 2
A24: Account 020 | B24: 10 | C24: 9 | D24: 15 | E24: 34
A25: Account 021 | B25: 8 | D25: 4 | E25: 12
A26: Account 022 | B26: 3 | C26: 2 | D26: 4 | E26: 9
A27: Account 023 | B27: 13 | C27: 4 | D27: 13 | E27: 30
A28: Account 024 | B28: 7 | C28: 2 | D28: 6 | E28: 15
A29: Account 025 | B29: 50 | C29: 26 | D29: 44 | E29: 120
A30: Account 026 | B30: 1 | D30: 1 | E30: 2
A31: Account 030 | B31: 4 | C31: 5 | E31: 9
A32: Account 031 | B32: 2 | C32: 1 | D32: 4 | E32: 7
A33: Account 032 | B33: 13 | C33: 5 | D33: 7 | E33: 25
A34: Account 033 | B34: 3 | C34: 1 | D34: 6 | E34: 10
A35: Account 034 | B35: 1 | C35: 1 | E35: 2
A36: Account 035 | B36: 2 | C36: 1 | D36: 2 | E36: 5
A37: Account 036 | B37: 3 | E37: 3
A38: Account 037 | B38: 3 | E38: 3
A39: Account 038 | B39: 5 | C39: 3 | D39: 7 | E39: 15
A40: Account 039 | B40: 1 | C40: 5 | D40: 1 | E40: 7
A41: Account 040 | B41: 3 | D41: 2 | E41: 5
A42: Account 041 | B42: 1 | E42: 1
...

Sheet Validation Tracker
A1: Count of Order Pay | B1: Column Labels
A2: Account Name | B2: Q1 | C2: Q2 | D2: Q3 | E2: Total volume at Risk | F2: Customer Status | G2: % Volume Lost
A3: Account 002 | B3: 2 | E3: =B3 -> 2 | F3: =IF(AND(B3>0,D3=0),"STILL CHURNED", IF(AND(B3>0,C3=0,D3>0),"Recovered in Q3", IF(AND(B3>0,D3>0,IFERROR((D3-B3)/B3,0)<=-0.4),"CRITICAL DECLINE", IF(AND(B3=0,C3=0,D3>0,D3<=2),"New Trial Account", IF(AND(B3=0,D3=0),"Inactive / One-Off", "Stable / Active"))))) -> STILL CHURNED | G3: =IFERROR((D3-B3)/B3,0) -> -1
A4: Account 004 | B4: 4 | E4: =B4 -> 4 | F4: =IF(AND(B4>0,D4=0),"STILL CHURNED", IF(AND(B4>0,C4=0,D4>0),"Recovered in Q3", IF(AND(B4>0,D4>0,IFERROR((D4-B4)/B4,0)<=-0.4),"CRITICAL DECLINE", IF(AND(B4=0,C4=0,D4>0,D4<=2),"New Trial Account", IF(AND(B4=0,D4=0),"Inactive / One-Off", "Stable / Active"))))) -> STILL CHURNED | G4: =IFERROR((D4-B4)/B4,0) -> -1 | I4: Q2 total order count | J4: =SUM(C3:C95) -> 339
A5: Account 016 | B5: 1 | E5: =B5 -> 1 | F5: =IF(AND(B5>0,D5=0),"STILL CHURNED", IF(AND(B5>0,C5=0,D5>0),"Recovered in Q3", IF(AND(B5>0,D5>0,IFERROR((D5-B5)/B5,0)<=-0.4),"CRITICAL DECLINE", IF(AND(B5=0,C5=0,D5>0,D5<=2),"New Trial Account", IF(AND(B5=0,D5=0),"Inactive / One-Off", "Stable / Active"))))) -> STILL CHURNED | G5: =IFERROR((D5-B5)/B5,0) -> -1
A6: Account 019 | B6: 1 | C6: 1 | E6: =B6 -> 1 | F6: =IF(AND(B6>0,D6=0),"STILL CHURNED", IF(AND(B6>0,C6=0,D6>0),"Recovered in Q3", IF(AND(B6>0,D6>0,IFERROR((D6-B6)/B6,0)<=-0.4),"CRITICAL DECLINE", IF(AND(B6=0,C6=0,D6>0,D6<=2),"New Trial Account", IF(AND(B6=0,D6=0),"Inactive / One-Off", "Stable / Active"))))) -> STILL CHURNED | G6: =IFERROR((D6-B6)/B6,0) -> -1
A7: Account 030 | B7: 4 | C7: 5 | E7: =B7 -> 4 | F7: =IF(AND(B7>0,D7=0),"STILL CHURNED", IF(AND(B7>0,C7=0,D7>0),"Recovered in Q3", IF(AND(B7>0,D7>0,IFERROR((D7-B7)/B7,0)<=-0.4),"CRITICAL DECLINE", IF(AND(B7=0,C7=0,D7>0,D7<=2),"New Trial Account", IF(AND(B7=0,D7=0),"Inactive / One-Off", "Stable / Active"))))) -> STILL CHURNED | G7: =IFERROR((D7-B7)/B7,0) -> -1
A8: Account 034 | B8: 1 | C8: 1 | E8: =B8 -> 1 | F8: =IF(AND(B8>0,D8=0),"STILL CHURNED", IF(AND(B8>0,C8=0,D8>0),"Recovered in Q3", IF(AND(B8>0,D8>0,IFERROR((D8-B8)/B8,0)<=-0.4),"CRITICAL DECLINE", IF(AND(B8=0,C8=0,D8>0,D8<=2),"New Trial Account", IF(AND(B8=0,D8=0),"Inactive / One-Off", "Stable / Active"))))) -> STILL CHURNED | G8: =IFERROR((D8-B8)/B8,0) -> -1
A9: Account 036 | B9: 3 | E9: =B9 -> 3 | F9: =IF(AND(B9>0,D9=0),"STILL CHURNED", IF(AND(B9>0,C9=0,D9>0),"Recovered in Q3", IF(AND(B9>0,D9>0,IFERROR((D9-B9)/B9,0)<=-0.4),"CRITICAL DECLINE", IF(AND(B9=0,C9=0,D9>0,D9<=2),"New Trial Account", IF(AND(B9=0,D9=0),"Inactive / One-Off", "Stable / Active"))))) -> STILL CHURNED | G9: =IFERROR((D9-B9)/B9,0) -> -1
A10: Account 037 | B10: 3 | E10: =B10 -> 3 | F10: =IF(AND(B10>0,D10=0),"STILL CHURNED", IF(AND(B10>0,C10=0,D10>0),"Recovered in Q3", IF(AND(B10>0,D10>0,IFERROR((D10-B10)/B10,0)<=-0.4),"CRITICAL DECLINE", IF(AND(B10=0,C10=0,D10>0,D10<=2),"New Trial Account", IF(AND(B10=0,D10=0),"Inactive / One-Off", "Stable / Active"))))) -> STILL CHURNED | G10: =IFERROR((D10-B10)/B10,0) -> -1
A11: Account 041 | B11: 1 | E11: =B11 -> 1 | F11: =IF(AND(B11>0,D11=0),"STILL CHURNED", IF(AND(B11>0,C11=0,D11>0),"Recovered in Q3", IF(AND(B11>0,D11>0,IFERROR((D11-B11)/B11,0)<=-0.4),"CRITICAL DECLINE", IF(AND(B11=0,C11=0,D11>0,D11<=2),"New Trial Account", IF(AND(B11=0,D11=0),"Inactive / One-Off", "Stable / Active"))))) -> STILL CHURNED | G11: =IFERROR((D11-B11)/B11,0) -> -1
A12: Account 043 | B12: 1 | E12: =B12 -> 1 | F12: =IF(AND(B12>0,D12=0),"STILL CHURNED", IF(AND(B12>0,C12=0,D12>0),"Recovered in Q3", IF(AND(B12>0,D12>0,IFERROR((D12-B12)/B12,0)<=-0.4),"CRITICAL DECLINE", IF(AND(B12=0,C12=0,D12>0,D12<=2),"New Trial Account", IF(AND(B12=0,D12=0),"Inactive / One-Off", "Stable / Active"))))) -> STILL CHURNED | G12: =IFERROR((D12-B12)/B12,0) -> -1
A13: Account 045 | B13: 1 | E13: =B13 -> 1 | F13: =IF(AND(B13>0,D13=0),"STILL CHURNED", IF(AND(B13>0,C13=0,D13>0),"Recovered in Q3", IF(AND(B13>0,D13>0,IFERROR((D13-B13)/B13,0)<=-0.4),"CRITICAL DECLINE", IF(AND(B13=0,C13=0,D13>0,D13<=2),"New Trial Account", IF(AND(B13=0,D13=0),"Inactive / One-Off", "Stable / Active"))))) -> STILL CHURNED | G13: =IFERROR((D13-B13)/B13,0) -> -1
A14: Account 047 | B14: 1 | E14: =B14 -> 1 | F14: =IF(AND(B14>0,D14=0),"STILL CHURNED", IF(AND(B14>0,C14=0,D14>0),"Recovered in Q3", IF(AND(B14>0,D14>0,IFERROR((D14-B14)/B14,0)<=-0.4),"CRITICAL DECLINE", IF(AND(B14=0,C14=0,D14>0,D14<=2),"New Trial Account", IF(AND(B14=0,D14=0),"Inactive / One-Off", "Stable / Active"))))) -> STILL CHURNED | G14: =IFERROR((D14-B14)/B14,0) -> -1
A15: Account 049 | B15: 3 | E15: =B15 -> 3 | F15: =IF(AND(B15>0,D15=0),"STILL CHURNED", IF(AND(B15>0,C15=0,D15>0),"Recovered in Q3", IF(AND(B15>0,D15>0,IFERROR((D15-B15)/B15,0)<=-0.4),"CRITICAL DECLINE", IF(AND(B15=0,C15=0,D15>0,D15<=2),"New Trial Account", IF(AND(B15=0,D15=0),"Inactive / One-Off", "Stable / Active"))))) -> STILL CHURNED | G15: =IFERROR((D15-B15)/B15,0) -> -1
A16: Account 051 | B16: 2 | C16: 3 | E16: =B16 -> 2 | F16: =IF(AND(B16>0,D16=0),"STILL CHURNED", IF(AND(B16>0,C16=0,D16>0),"Recovered in Q3", IF(AND(B16>0,D16>0,IFERROR((D16-B16)/B16,0)<=-0.4),"CRITICAL DECLINE", IF(AND(B16=0,C16=0,D16>0,D16<=2),"New Trial Account", IF(AND(B16=0,D16=0),"Inactive / One-Off", "Stable / Active"))))) -> STILL CHURNED | G16: =IFERROR((D16-B16)/B16,0) -> -1
A17: Account 052 | B17: 2 | C17: 1 | E17: =B17 -> 2 | F17: =IF(AND(B17>0,D17=0),"STILL CHURNED", IF(AND(B17>0,C17=0,D17>0),"Recovered in Q3", IF(AND(B17>0,D17>0,IFERROR((D17-B17)/B17,0)<=-0.4),"CRITICAL DECLINE", IF(AND(B17=0,C17=0,D17>0,D17<=2),"New Trial Account", IF(AND(B17=0,D17=0),"Inactive / One-Off", "Stable / Active"))))) -> STILL CHURNED | G17: =IFERROR((D17-B17)/B17,0) -> -1
A18: Account 053 | B18: 5 | E18: =B18 -> 5 | F18: =IF(AND(B18>0,D18=0),"STILL CHURNED", IF(AND(B18>0,C18=0,D18>0),"Recovered in Q3", IF(AND(B18>0,D18>0,IFERROR((D18-B18)/B18,0)<=-0.4),"CRITICAL DECLINE", IF(AND(B18=0,C18=0,D18>0,D18<=2),"New Trial Account", IF(AND(B18=0,D18=0),"Inactive / One-Off", "Stable / Active"))))) -> STILL CHURNED | G18: =IFERROR((D18-B18)/B18,0) -> -1
A19: Account 056 | B19: 1 | C19: 1 | E19: =B19 -> 1 | F19: =IF(AND(B19>0,D19=0),"STILL CHURNED", IF(AND(B19>0,C19=0,D19>0),"Recovered in Q3", IF(AND(B19>0,D19>0,IFERROR((D19-B19)/B19,0)<=-0.4),"CRITICAL DECLINE", IF(AND(B19=0,C19=0,D19>0,D19<=2),"New Trial Account", IF(AND(B19=0,D19=0),"Inactive / One-Off", "Stable / Active"))))) -> STILL CHURNED | G19: =IFERROR((D19-B19)/B19,0) -> -1
A20: Account 057 | B20: 1 | E20: =B20 -> 1 | F20: =IF(AND(B20>0,D20=0),"STILL CHURNED", IF(AND(B20>0,C20=0,D20>0),"Recovered in Q3", IF(AND(B20>0,D20>0,IFERROR((D20-B20)/B20,0)<=-0.4),"CRITICAL DECLINE", IF(AND(B20=0,C20=0,D20>0,D20<=2),"New Trial Account", IF(AND(B20=0,D20=0),"Inactive / One-Off", "Stable / Active"))))) -> STILL CHURNED | G20: =IFERROR((D20-B20)/B20,0) -> -1
A21: Account 059 | B21: 2 | E21: =B21 -> 2 | F21: =IF(AND(B21>0,D21=0),"STILL CHURNED", IF(AND(B21>0,C21=0,D21>0),"Recovered in Q3", IF(AND(B21>0,D21>0,IFERROR((D21-B21)/B21,0)<=-0.4),"CRITICAL DECLINE", IF(AND(B21=0,C21=0,D21>0,D21<=2),"New Trial Account", IF(AND(B21=0,D21=0),"Inactive / One-Off", "Stable / Active"))))) -> STILL CHURNED | G21: =IFERROR((D21-B21)/B21,0) -> -1
A22: Account 060 | B22: 1 | C22: 1 | E22: =B22 -> 1 | F22: =IF(AND(B22>0,D22=0),"STILL CHURNED", IF(AND(B22>0,C22=0,D22>0),"Recovered in Q3", IF(AND(B22>0,D22>0,IFERROR((D22-B22)/B22,0)<=-0.4),"CRITICAL DECLINE", IF(AND(B22=0,C22=0,D22>0,D22<=2),"New Trial Account", IF(AND(B22=0,D22=0),"Inactive / One-Off", "Stable / Active"))))) -> STILL CHURNED | G22: =IFERROR((D22-B22)/B22,0) -> -1
A23: Account 062 | B23: 1 | C23: 2 | E23: =B23 -> 1 | F23: =IF(AND(B23>0,D23=0),"STILL CHURNED", IF(AND(B23>0,C23=0,D23>0),"Recovered in Q3", IF(AND(B23>0,D23>0,IFERROR((D23-B23)/B23,0)<=-0.4),"CRITICAL DECLINE", IF(AND(B23=0,C23=0,D23>0,D23<=2),"New Trial Account", IF(AND(B23=0,D23=0),"Inactive / One-Off", "Stable / Active"))))) -> STILL CHURNED | G23: =IFERROR((D23-B23)/B23,0) -> -1
A24: Account 063 | B24: 2 | C24: 1 | E24: =B24 -> 2 | F24: =IF(AND(B24>0,D24=0),"STILL CHURNED", IF(AND(B24>0,C24=0,D24>0),"Recovered in Q3", IF(AND(B24>0,D24>0,IFERROR((D24-B24)/B24,0)<=-0.4),"CRITICAL DECLINE", IF(AND(B24=0,C24=0,D24>0,D24<=2),"New Trial Account", IF(AND(B24=0,D24=0),"Inactive / One-Off", "Stable / Active"))))) -> STILL CHURNED | G24: =IFERROR((D24-B24)/B24,0) -> -1
A25: Account 064 | B25: 2 | E25: =B25 -> 2 | F25: =IF(AND(B25>0,D25=0),"STILL CHURNED", IF(AND(B25>0,C25=0,D25>0),"Recovered in Q3", IF(AND(B25>0,D25>0,IFERROR((D25-B25)/B25,0)<=-0.4),"CRITICAL DECLINE", IF(AND(B25=0,C25=0,D25>0,D25<=2),"New Trial Account", IF(AND(B25=0,D25=0),"Inactive / One-Off", "Stable / Active"))))) -> STILL CHURNED | G25: =IFERROR((D25-B25)/B25,0) -> -1
A26: Account 015 | B26: 12 | C26: 2 | D26: 3 | E26: =B26 -> 12 | F26: =IF(AND(B26>0,D26=0),"STILL CHURNED", IF(AND(B26>0,C26=0,D26>0),"Recovered in Q3", IF(AND(B26>0,D26>0,IFERROR((D26-B26)/B26,0)<=-0.4),"CRITICAL DECLINE", IF(AND(B26=0,C26=0,D26>0,D26<=2),"New Trial Account", IF(AND(B26=0,D26=0),"Inactive / One-Off", "Stable / Active"))))) -> CRITICAL DECLINE | G26: =IFERROR((D26-B26)/B26,0) -> -0.75
A27: Account 012 | B27: 15 | C27: 12 | D27: 4 | E27: =B27 -> 15 | F27: =IF(AND(B27>0,D27=0),"STILL CHURNED", IF(AND(B27>0,C27=0,D27>0),"Recovered in Q3", IF(AND(B27>0,D27>0,IFERROR((D27-B27)/B27,0)<=-0.4),"CRITICAL DECLINE", IF(AND(B27=0,C27=0,D27>0,D27<=2),"New Trial Account", IF(AND(B27=0,D27=0),"Inactive / One-Off", "Stable / Active"))))) -> CRITICAL DECLINE | G27: =IFERROR((D27-B27)/B27,0) -> -0.73333333
A28: Account 008 | B28: 14 | C28: 3 | D28: 4 | E28: =B28 -> 14 | F28: =IF(AND(B28>0,D28=0),"STILL CHURNED", IF(AND(B28>0,C28=0,D28>0),"Recovered in Q3", IF(AND(B28>0,D28>0,IFERROR((D28-B28)/B28,0)<=-0.4),"CRITICAL DECLINE", IF(AND(B28=0,C28=0,D28>0,D28<=2),"New Trial Account", IF(AND(B28=0,D28=0),"Inactive / One-Off", "Stable / Active"))))) -> CRITICAL DECLINE | G28: =IFERROR((D28-B28)/B28,0) -> -0.71428571
A29: Account 044 | B29: 5 | C29: 2 | D29: 2 | E29: =B29 -> 5 | F29: =IF(AND(B29>0,D29=0),"STILL CHURNED", IF(AND(B29>0,C29=0,D29>0),"Recovered in Q3", IF(AND(B29>0,D29>0,IFERROR((D29-B29)/B29,0)<=-0.4),"CRITICAL DECLINE", IF(AND(B29=0,C29=0,D29>0,D29<=2),"New Trial Account", IF(AND(B29=0,D29=0),"Inactive / One-Off", "Stable / Active"))))) -> CRITICAL DECLINE | G29: =IFERROR((D29-B29)/B29,0) -> -0.6
A30: Account 013 | B30: 4 | C30: 1 | D30: 2 | E30: =B30 -> 4 | F30: =IF(AND(B30>0,D30=0),"STILL CHURNED", IF(AND(B30>0,C30=0,D30>0),"Recovered in Q3", IF(AND(B30>0,D30>0,IFERROR((D30-B30)/B30,0)<=-0.4),"CRITICAL DECLINE", IF(AND(B30=0,C30=0,D30>0,D30<=2),"New Trial Account", IF(AND(B30=0,D30=0),"Inactive / One-Off", "Stable / Active"))))) -> CRITICAL DECLINE | G30: =IFERROR((D30-B30)/B30,0) -> -0.5
A31: Account 021 | B31: 8 | D31: 4 | E31: =B31 -> 8 | F31: =IF(AND(B31>0,D31=0),"STILL CHURNED", IF(AND(B31>0,C31=0,D31>0),"Recovered in Q3", IF(AND(B31>0,D31>0,IFERROR((D31-B31)/B31,0)<=-0.4),"CRITICAL DECLINE", IF(AND(B31=0,C31=0,D31>0,D31<=2),"New Trial Account", IF(AND(B31=0,D31=0),"Inactive / One-Off", "Stable / Active"))))) -> Recovered in Q3 | G31: =IFERROR((D31-B31)/B31,0) -> -0.5
A32: Account 032 | B32: 13 | C32: 5 | D32: 7 | E32: =B32 -> 13 | F32: =IF(AND(B32>0,D32=0),"STILL CHURNED", IF(AND(B32>0,C32=0,D32>0),"Recovered in Q3", IF(AND(B32>0,D32>0,IFERROR((D32-B32)/B32,0)<=-0.4),"CRITICAL DECLINE", IF(AND(B32=0,C32=0,D32>0,D32<=2),"New Trial Account", IF(AND(B32=0,D32=0),"Inactive / One-Off", "Stable / Active"))))) -> CRITICAL DECLINE | G32: =IFERROR((D32-B32)/B32,0) -> -0.46153846
A33: Account 006 | B33: 25 | C33: 17 | D33: 14 | E33: =B33 -> 25 | F33: =IF(AND(B33>0,D33=0),"STILL CHURNED", IF(AND(B33>0,C33=0,D33>0),"Recovered in Q3", IF(AND(B33>0,D33>0,IFERROR((D33-B33)/B33,0)<=-0.4),"CRITICAL DECLINE", IF(AND(B33=0,C33=0,D33>0,D33<=2),"New Trial Account", IF(AND(B33=0,D33=0),"Inactive / One-Off", "Stable / Active"))))) -> CRITICAL DECLINE | G33: =IFERROR((D33-B33)/B33,0) -> -0.44
A34: Account 017 | B34: 27 | C34: 11 | D34: 16 | E34: =B34 -> 27 | F34: =IF(AND(B34>0,D34=0),"STILL CHURNED", IF(AND(B34>0,C34=0,D34>0),"Recovered in Q3", IF(AND(B34>0,D34>0,IFERROR((D34-B34)/B34,0)<=-0.4),"CRITICAL DECLINE", IF(AND(B34=0,C34=0,D34>0,D34<=2),"New Trial Account", IF(AND(B34=0,D34=0),"Inactive / One-Off", "Stable / Active"))))) -> CRITICAL DECLINE | G34: =IFERROR((D34-B34)/B34,0) -> -0.40740741
A35: Account 040 | B35: 3 | D35: 2 | E35: =B35 -> 3 | F35: =IF(AND(B35>0,D35=0),"STILL CHURNED", IF(AND(B35>0,C35=0,D35>0),"Recovered in Q3", IF(AND(B35>0,D35>0,IFERROR((D35-B35)/B35,0)<=-0.4),"CRITICAL DECLINE", IF(AND(B35=0,C35=0,D35>0,D35<=2),"New Trial Account", IF(AND(B35=0,D35=0),"Inactive / One-Off", "Stable / Active"))))) -> Recovered in Q3 | G35: =IFERROR((D35-B35)/B35,0) -> -0.33333333
A36: Account 010 | B36: 68 | C36: 12 | D36: 58 | E36: =B36 -> 68 | F36: =IF(AND(B36>0,D36=0),"STILL CHURNED", IF(AND(B36>0,C36=0,D36>0),"Recovered in Q3", IF(AND(B36>0,D36>0,IFERROR((D36-B36)/B36,0)<=-0.4),"CRITICAL DECLINE", IF(AND(B36=0,C36=0,D36>0,D36<=2),"New Trial Account", IF(AND(B36=0,D36=0),"Inactive / One-Off", "Stable / Active"))))) -> Stable / Active | G36: =IFERROR((D36-B36)/B36,0) -> -0.14705882
A37: Account 014 | B37: 7 | C37: 8 | D37: 6 | E37: =B37 -> 7 | F37: =IF(AND(B37>0,D37=0),"STILL CHURNED", IF(AND(B37>0,C37=0,D37>0),"Recovered in Q3", IF(AND(B37>0,D37>0,IFERROR((D37-B37)/B37,0)<=-0.4),"CRITICAL DECLINE", IF(AND(B37=0,C37=0,D37>0,D37<=2),"New Trial Account", IF(AND(B37=0,D37=0),"Inactive / One-Off", "Stable / Active"))))) -> Stable / Active | G37: =IFERROR((D37-B37)/B37,0) -> -0.14285714
A38: Account 024 | B38: 7 | C38: 2 | D38: 6 | E38: =B38 -> 7 | F38: =IF(AND(B38>0,D38=0),"STILL CHURNED", IF(AND(B38>0,C38=0,D38>0),"Recovered in Q3", IF(AND(B38>0,D38>0,IFERROR((D38-B38)/B38,0)<=-0.4),"CRITICAL DECLINE", IF(AND(B38=0,C38=0,D38>0,D38<=2),"New Trial Account", IF(AND(B38=0,D38=0),"Inactive / One-Off", "Stable / Active"))))) -> Stable / Active | G38: =IFERROR((D38-B38)/B38,0) -> -0.14285714
A39: Account 025 | B39: 50 | C39: 26 | D39: 44 | E39: =B39 -> 50 | F39: =IF(AND(B39>0,D39=0),"STILL CHURNED", IF(AND(B39>0,C39=0,D39>0),"Recovered in Q3", IF(AND(B39>0,D39>0,IFERROR((D39-B39)/B39,0)<=-0.4),"CRITICAL DECLINE", IF(AND(B39=0,C39=0,D39>0,D39<=2),"New Trial Account", IF(AND(B39=0,D39=0),"Inactive / One-Off", "Stable / Active"))))) -> Stable / Active | G39: =IFERROR((D39-B39)/B39,0) -> -0.12
A40: Account 023 | B40: 13 | C40: 4 | D40: 13 | E40: =B40 -> 13 | F40: =IF(AND(B40>0,D40=0),"STILL CHURNED", IF(AND(B40>0,C40=0,D40>0),"Recovered in Q3", IF(AND(B40>0,D40>0,IFERROR((D40-B40)/B40,0)<=-0.4),"CRITICAL DECLINE", IF(AND(B40=0,C40=0,D40>0,D40<=2),"New Trial Account", IF(AND(B40=0,D40=0),"Inactive / One-Off", "Stable / Active"))))) -> Stable / Active | G40: =IFERROR((D40-B40)/B40,0) -> 0
...

Sheet KPI
A1: KPIS | B1: VALUE
A2: Total Customer Account | B2: ='Recovery Analysis'!G14 -> 93
A3: Q1 Total Orders | B3: ='Recovery Analysis'!G15 -> 524
A4: Q3 Total Orders | B4: ='Recovery Analysis'!G16 -> 568
A5: Order Volume Growth | B5: =(B4-B3)/B3 -> 0.083969466
A6: At-Risk Accounts | B6: =23+8 -> 31
A7: At-Risk Account Rate | B7: =B6/B2 -> 0.33333333

Sheet Anonymized data
A1: Order Id | B1: Portfolio Account Name | C1: Portfolio Parent customer Code | D1: Order Pay | E1: Quarter
A2: ORD-000001 | B2: Account 001 | C2: PA-001 | D2: 66100 | E2: Q1
A3: ORD-000002 | B3: Account 002 | C3: PA-002 | D3: 113300 | E3: Q1
A4: ORD-000003 | B4: Account 002 | C4: PA-002 | D4: 92500 | E4: Q1
A5: ORD-000004 | B5: Account 003 | C5: PA-003 | D5: 141300 | E5: Q1
A6: ORD-000005 | B6: Account 004 | C6: PA-004 | D6: 52500 | E6: Q1
A7: ORD-000006 | B7: Account 004 | C7: PA-004 | D7: 204600 | E7: Q1
A8: ORD-000007 | B8: Account 005 | C8: PA-005 | D8: 131900 | E8: Q1
A9: ORD-000008 | B9: Account 006 | C9: PA-006 | D9: 49300 | E9: Q1
A10: ORD-000009 | B10: Account 007 | C10: PA-007 | D10: 52000 | E10: Q1
A11: ORD-000010 | B11: Account 007 | C11: PA-007 | D11: 39400 | E11: Q1
A12: ORD-000011 | B12: Account 008 | C12: PA-008 | D12: 102000 | E12: Q1
A13: ORD-000012 | B13: Account 009 | C13: PA-009 | D13: 41400 | E13: Q1
... A1432: ORD-001431 | B1432: Account 023 | C1432: PA-023 | D1432: 14000 | E1432: Q3
